Error creating database from model: RelationshipProperty.__init__() got an unexpected keyword argument 'order_back_populates'

Why did retry not kick in?

Can we just delete the last response and repeat??

How would this affect other retry scenarios?
    - single file
    - directory

als genai --using=system/genai/temp/customer_orders_retry  # worked